[ 2025-05-12 09:38:36,283 ] 17 __main__ - INFO - STARTING PIPELINE...
[ 2025-05-12 09:38:36,283 ] 82 __main__ - INFO - Extracting detail files
[ 2025-05-12 09:38:36,284 ] 96 __main__ - INFO - Extracting concept files
[ 2025-05-12 09:38:47,893 ] 115 __main__ - INFO - CREATING MASTERLIST
[ 2025-05-12 09:38:51,013 ] 118 __main__ - INFO - MASTERLIST CREATED SUCCESSFULLY
[ 2025-05-12 09:38:51,075 ] 128 __main__ - INFO - STARTING NEO4J LOADER...
[ 2025-05-12 09:38:55,158 ] 132 __main__ - ERROR - AN ERROR OCCURRED WHILE RUNNING THE NEO4J LOADER
Traceback (most recent call last):
  File "C:\Users\PrinciaFernandes\anaconda3\Lib\site-packages\neo4j\_async_compat\network\_bolt_socket.py", line 409, in _connect_secure
    s.connect(resolved_address)
ConnectionRefusedError: [WinError 10061] No connection could be made because the target machine actively refused it

The above exception was the direct cause of the following exception:

Traceback (most recent call last):
  File "C:\Users\PrinciaFernandes\anaconda3\Lib\site-packages\neo4j\_sync\io\_bolt_socket.py", line 328, in connect
    s = cls._connect_secure(
        ^^^^^^^^^^^^^^^^^^^^
  File "C:\Users\PrinciaFernandes\anaconda3\Lib\site-packages\neo4j\_async_compat\network\_bolt_socket.py", line 426, in _connect_secure
    raise ServiceUnavailable(
neo4j.exceptions.ServiceUnavailable: Failed to establish connection to ResolvedIPv6Address(('::1', 7687, 0, 0)) (reason [WinError 10061] No connection could be made because the target machine actively refused it)

The above exception was the direct cause of the following exception:

Traceback (most recent call last):
  File "C:\Users\PrinciaFernandes\Mresult\Phenomix\main.py", line 129, in <module>
    push_to_neo4j(masterlist,detail_files,concept_files)
  File "C:\Users\PrinciaFernandes\Mresult\Phenomix\src\database\neo4j.py", line 11, in push_to_neo4j
    session.run("""
  File "C:\Users\PrinciaFernandes\anaconda3\Lib\site-packages\neo4j\_sync\work\session.py", line 313, in run
    self._connect(self._config.default_access_mode)
  File "C:\Users\PrinciaFernandes\anaconda3\Lib\site-packages\neo4j\_sync\work\session.py", line 136, in _connect
    super()._connect(
  File "C:\Users\PrinciaFernandes\anaconda3\Lib\site-packages\neo4j\_sync\work\workspace.py", line 199, in _connect
    self._connection = self._pool.acquire(**acquire_kwargs_)
                       ^^^^^^^^^^^^^^^^^^^^^^^^^^^^^^^^^^^^^
  File "C:\Users\PrinciaFernandes\anaconda3\Lib\site-packages\neo4j\_sync\io\_pool.py", line 662, in acquire
    return self._acquire(
           ^^^^^^^^^^^^^^
  File "C:\Users\PrinciaFernandes\anaconda3\Lib\site-packages\neo4j\_sync\io\_pool.py", line 408, in _acquire
    return connection_creator()
           ^^^^^^^^^^^^^^^^^^^^
  File "C:\Users\PrinciaFernandes\anaconda3\Lib\site-packages\neo4j\_sync\io\_pool.py", line 230, in connection_creator
    connection = self.opener(
                 ^^^^^^^^^^^^
  File "C:\Users\PrinciaFernandes\anaconda3\Lib\site-packages\neo4j\_sync\io\_pool.py", line 624, in opener
    return Bolt.open(
           ^^^^^^^^^^
  File "C:\Users\PrinciaFernandes\anaconda3\Lib\site-packages\neo4j\_sync\io\_bolt.py", line 369, in open
    s, protocol_version, handshake, data = BoltSocket.connect(
                                           ^^^^^^^^^^^^^^^^^^^
  File "C:\Users\PrinciaFernandes\anaconda3\Lib\site-packages\neo4j\_sync\io\_bolt_socket.py", line 376, in connect
    raise ServiceUnavailable(
neo4j.exceptions.ServiceUnavailable: Couldn't connect to localhost:7687 (resolved to ('[::1]:7687', '127.0.0.1:7687')):
Failed to establish connection to ResolvedIPv6Address(('::1', 7687, 0, 0)) (reason [WinError 10061] No connection could be made because the target machine actively refused it)
Failed to establish connection to ResolvedIPv4Address(('127.0.0.1', 7687)) (reason [WinError 10061] No connection could be made because the target machine actively refused it)
